<?xml version="1.0"?>
<robot xmlns:xacro="http://www.ros.org/wiki/xacro" >

 <material name="white">
    <color rgba="1 1 1 1"/>
</material>

<material name="orange">
    <color rgba="1 0.3 0.1 1"/>
</material>

<material name="blue">
    <color rgba="0.2 0.2 1 1"/>
</material>

<material name="yellow">
    <color rgba="1 1 0 1"/>
</material>

<material name="black">
    <color rgba="0 0 0 1"/>
</material>

<link name="base_link">
</link>

<joint name="chassis_joint" type="fixed">
    <parent link="base_link"/>
    <child link="chassis"/>
    <origin xyz="-0.1 0 0"/>
</joint>

<link name="chassis">
    <visual>
        <origin xyz="0.2 0 0.0375" rpy="0 0 0"/>
        <geometry>
            <box size="0.6 0.3 0.005"/>
        </geometry>
        <material name="orange"/>
    </visual>
    
    <collision>
        <origin xyz="0.2 0 0.0375" rpy="0 0 0"/>
        <geometry>
            <box size="0.6 0.3 0.005"/>
        </geometry>
        <material name="orange"/>
    </collision>
    
    <xacro:inertial_box mass="0.5" x="0.6" y="0.3" z="0.005">
        <origin xyz="0.2 0 0.0375" rpy="0 0 0"/>
    </xacro:inertial_box>    
</link>

<!-- LEFT WHEEL -->

<joint name="left_wheel_joint" type="continuous">
    <parent link="base_link"/>
    <child link="left_wheel"/>
    <origin xyz="0 0.175 0" rpy="-${pi/2} 0 0"/>
    <axis xyz="0 0 1"/>
</joint>

<link name="left_wheel">
    <visual>
        <geometry>
            <cylinder length="0.04" radius="0.05" />
        </geometry>
        <material name="yellow"/>
    </visual>
    
    <collision>
        <geometry>
            <cylinder length="0.04" radius="0.05" />
        </geometry>
        <material name="yellow"/>
    </collision>
    
    <xacro:inertial_cylinder mass="0.1" length="0.04" radius="0.05">
        <origin xyz="0 0 0" rpy="0 0 0"/>
    </xacro:inertial_cylinder>
</link>

<!-- RIGHT WHEEL -->

<joint name="right_wheel_joint" type="continuous">
    <parent link="base_link"/>
    <child link="right_wheel"/>
    <origin xyz="0 -0.175 0" rpy="${pi/2} 0 0"/>
    <axis xyz="0 0 -1"/>
</joint>

<link name="right_wheel">
    <visual>
        <geometry>
            <cylinder length="0.04" radius="0.05" />
        </geometry>
        <material name="yellow"/>
    </visual>
    <collision>
        <geometry>
            <cylinder length="0.04" radius="0.05" />
        </geometry>
        <material name="yellow"/>
    </collision>
    
    <xacro:inertial_cylinder mass="0.1" length="0.04" radius="0.05">
        <origin xyz="0 0 0" rpy="0 0 0"/>
    </xacro:inertial_cylinder>
        
</link>

<!-- CASTER WHEEL -->

<joint name="caster_wheel_joint" type="fixed">
    <parent link="chassis"/>
    <child link="caster_wheel"/>
    <origin xyz="0.4 0 -0.01" rpy="${pi/2} 0 0"/>
</joint>

<link name="caster_wheel">
    <visual>
        <geometry>
            <cylinder length="0.02" radius="0.04" />
        </geometry>
        <material name="white"/>
    </visual>

    <collision>
        <geometry>
            <cylinder length="0.02" radius="0.04" />
        </geometry>
        <material name="white"/>
    </collision>

    <xacro:inertial_cylinder mass="0.1" length="0.02" radius="0.04">
        <origin xyz="0 0 0" rpy="0 0 0"/>
    </xacro:inertial_cylinder>
</link>

</robot>
